<?xml version="1.0"?>
<robot xmlns:xacro="http://www.ros.org/wiki/xacro" name="ika_robot">

  <link name="base_footprint"/>

  <joint name="base_footprint_joint" type="fixed">
    <parent link="base_footprint"/>
    <child link="base_link"/>
    <origin xyz="0 0 0.2" rpy="0 0 0"/>
  </joint>

  <link name="base_link">
    <visual>
      <geometry>
        <box size="0.6 0.4 0.2"/>
      </geometry>
      <material name="blue">
        <color rgba="0 0 1 1"/>
      </material>
    </visual>
    <collision>
      <geometry>
        <box size="0.6 0.4 0.2"/>
      </geometry>
    </collision>
    <inertial>
      <mass value="10.0"/>
      <inertia ixx="0.1" ixy="0" ixz="0" iyy="0.1" iyz="0" izz="0.1"/>
    </inertial>
  </link>

  <xacro:macro name="wheel" params="prefix x_reflect y_reflect">
    <link name="${prefix}_wheel">
      <visual>
        <origin xyz="0 0 0" rpy="${pi/2} 0 0"/>
        <geometry>
          <cylinder radius="0.1" length="0.05"/>
        </geometry>
        <material name="black">
          <color rgba="0 0 0 1"/>
        </material>
      </visual>
      <collision>
        <origin xyz="0 0 0" rpy="${pi/2} 0 0"/>
        <geometry>
          <cylinder radius="0.1" length="0.05"/>
        </geometry>
      </collision>
      <inertial>
        <mass value="0.5"/>
        <inertia ixx="0.01" ixy="0" ixz="0" iyy="0.01" iyz="0" izz="0.01"/>
      </inertial>
    </link>

    <joint name="${prefix}_wheel_joint" type="continuous">
      <parent link="base_link"/>
      <child link="${prefix}_wheel"/>
      <origin xyz="${x_reflect*0.2} ${y_reflect*0.25} -0.1" rpy="0 0 0"/>
      <axis xyz="0 1 0"/>
    </joint>

    <gazebo reference="${prefix}_wheel">
      <material>Gazebo/Black</material>
      <mu1 value="1.0"/>
      <mu2 value="1.0"/>
    </gazebo>
  </xacro:macro>

  <xacro:wheel prefix="front_left"  x_reflect="1"  y_reflect="1" />
  <xacro:wheel prefix="front_right" x_reflect="1"  y_reflect="-1" />
  <xacro:wheel prefix="back_left"   x_reflect="-1" y_reflect="1" />
  <xacro:wheel prefix="back_right"  x_reflect="-1" y_reflect="-1" />

  <gazebo reference="base_link">
    <material>Gazebo/Blue</material>
  </gazebo>

  <gazebo>
    <plugin name="diff_drive" filename="libgazebo_ros_diff_drive.so">
      
      <num_wheel_pairs>2</num_wheel_pairs>
      
      <left_joint>front_left_wheel_joint</left_joint>
      <right_joint>front_right_wheel_joint</right_joint>
      
      <left_joint>back_left_wheel_joint</left_joint>
      <right_joint>back_right_wheel_joint</right_joint>

      <wheel_separation>0.5</wheel_separation>
      <wheel_separation>0.5</wheel_separation>
      <wheel_diameter>0.2</wheel_diameter>
      <wheel_diameter>0.2</wheel_diameter>

      <max_wheel_torque>20</max_wheel_torque>
      <max_wheel_acceleration>1.0</max_wheel_acceleration>

      <command_topic>cmd_vel</command_topic>
      <odometry_topic>odom</odometry_topic>
      <odometry_frame>odom</odometry_frame>
      <robot_base_frame>base_footprint</robot_base_frame>
      
      <publish_odom>true</publish_odom>
      <publish_odom_tf>true</publish_odom_tf>
      <publish_wheel_tf>true</publish_wheel_tf>
    </plugin>
  </gazebo>
</robot>